Workbook

Sheet ESCALA 01.01.2026
A1: NOME | B1: CPF | C1: GPID | D1: FROTA | E1: CAVALO | F1: MOTORISTA | G1: ESCALA | H1: APRESENTA | I1: VIAGEM | J1: VIAGEM | K1: VIAGEM | L1: DESTINO | O1: ////////////
A2: =VLOOKUP(F2,'CPF GPID NOME'!A:D,2,FALSE) -> ABEL JUSTINO DA SILVA | B2: =VLOOKUP(F2,'CPF GPID NOME'!A:C,3,FALSE) -> 14992534864 | C2: =VLOOKUP(F2,'CPF GPID NOME'!A:D,4,FALSE) -> 20200842 | D2: =VLOOKUP(F2,'FROTA ESC.ESPE'!A:C,3,FALSE) -> R21902 | E2: =VLOOKUP(F2,'FROTA ESC.ESPE'!A:C,2,FALSE) -> GBR8G23 | F2: ABEL | G2: 0.54166667 | I2: SC | L2: DHL - CDV BAURU, APÓS LIGAR NA ESCALA (DESCARREGAR NO CDV ÀS 08:00 HRS DO DIA 02/01)
A3: =VLOOKUP(F3,'CPF GPID NOME'!A:D,2,FALSE) -> OSMAR DE ALMEIDA | B3: =VLOOKUP(F3,'CPF GPID NOME'!A:C,3,FALSE) -> 12272348807 | C3: =VLOOKUP(F3,'CPF GPID NOME'!A:D,4,FALSE) -> 40108602 | D3: =VLOOKUP(F3,'FROTA ESC.ESPE'!A:C,3,FALSE) -> R21898 | E3: =VLOOKUP(F3,'FROTA ESC.ESPE'!A:C,2,FALSE) -> FXS7A81 | F3: ALMEIDA | G3: 0.54166667 | I3: SC | L3: DHL - CDV SÃO JOSE DO RIO PRETO, APÓS LIGAR NA ESCALA (DESCARREGAR NO CDV ÀS 09:00 HRS DO DIA 02/01)
A4: =VLOOKUP(F4,'CPF GPID NOME'!A:D,2,FALSE) -> CELSO PASSUELO | B4: =VLOOKUP(F4,'CPF GPID NOME'!A:C,3,FALSE) -> 10227524802 | C4: =VLOOKUP(F4,'CPF GPID NOME'!A:D,4,FALSE) -> 80109509 | D4: =VLOOKUP(F4,'FROTA ESC.ESPE'!A:C,3,FALSE) -> A51631 | E4: =VLOOKUP(F4,'FROTA ESC.ESPE'!A:C,2,FALSE) -> FII1356 | F4: CELSO (DHL) | G4: 0.54166667 | I4: SC | L4: DHL - CDV CAMPOS, APÓS LIGAR NA ESCALA
A5: =VLOOKUP(F5,'CPF GPID NOME'!A:D,2,FALSE) -> CLODOALDO ANDRINO ANTONANGELO | B5: =VLOOKUP(F5,'CPF GPID NOME'!A:C,3,FALSE) -> 26857000808 | C5: =VLOOKUP(F5,'CPF GPID NOME'!A:D,4,FALSE) -> 20216629 | D5: =VLOOKUP(F5,'FROTA ESC.ESPE'!A:C,3,FALSE) -> R11856 | E5: =VLOOKUP(F5,'FROTA ESC.ESPE'!A:C,2,FALSE) -> FIE2C01 | F5: CLODOALDO | G5: 0.54166667 | I5: SC | L5: DHL - CDV MEGA CURITIBA, APÓS COLETAR EM CURITIBA PARA DHL
A6: =VLOOKUP(F6,'CPF GPID NOME'!A:D,2,FALSE) -> EDSON RICARDO MARTIN | B6: =VLOOKUP(F6,'CPF GPID NOME'!A:C,3,FALSE) -> 17728032860 | C6: =VLOOKUP(F6,'CPF GPID NOME'!A:D,4,FALSE) -> 40260112 | D6: =VLOOKUP(F6,'FROTA ESC.ESPE'!A:C,3,FALSE) -> R21907 | E6: =VLOOKUP(F6,'FROTA ESC.ESPE'!A:C,2,FALSE) -> GFS7C01 | F6: EDSON RICARDO | G6: 0.54166667 | I6: SC | L6: DHL - FÁBRICA CURITIBA CIC, APÓS COLETAR EM CURITIBA PARA DHL
A7: =VLOOKUP(F7,'CPF GPID NOME'!A:D,2,FALSE) -> FLAVIO JOSE MARQUES DIAS | B7: =VLOOKUP(F7,'CPF GPID NOME'!A:C,3,FALSE) -> 6272872801 | C7: =VLOOKUP(F7,'CPF GPID NOME'!A:D,4,FALSE) -> 20200185 | D7: =VLOOKUP(F7,'FROTA ESC.ESPE'!A:C,3,FALSE) -> R21906 | E7: =VLOOKUP(F7,'FROTA ESC.ESPE'!A:C,2,FALSE) -> GFQ9F06 | F7: FLAVIO | G7: 0.54166667 | I7: SC | L7: DHL - FÁBRICA CURITIBA CIC, APÓS COLETAR EM CURITIBA PARA DHL
A8: =VLOOKUP(F8,'CPF GPID NOME'!A:D,2,FALSE) -> HUDSON JUNIOR BATISTA | B8: =VLOOKUP(F8,'CPF GPID NOME'!A:C,3,FALSE) -> 15056516899 | C8: =VLOOKUP(F8,'CPF GPID NOME'!A:D,4,FALSE) -> 20200840 | D8: =VLOOKUP(F8,'FROTA ESC.ESPE'!A:C,3,FALSE) -> R21908 | E8: =VLOOKUP(F8,'FROTA ESC.ESPE'!A:C,2,FALSE) -> GHG2I72 | F8: HUDSON | G8: 0.54166667 | I8: SC | L8: DHL - CDV SÃO JOSE DO RIO PRETO, APÓS LCOLETAR PALETES NO CDV PARA ITU (DESCARREGAR NO CDV ÀS 09:00 HRS DO DIA 02/01)
A9: =VLOOKUP(F9,'CPF GPID NOME'!A:D,2,FALSE) -> JAIR FRANCISCO ALVACETE | B9: =VLOOKUP(F9,'CPF GPID NOME'!A:C,3,FALSE) -> 11704755824 | C9: =VLOOKUP(F9,'CPF GPID NOME'!A:D,4,FALSE) -> 20200985 | D9: =VLOOKUP(F9,'FROTA ESC.ESPE'!A:C,3,FALSE) -> R21896 | E9: =VLOOKUP(F9,'FROTA ESC.ESPE'!A:C,2,FALSE) -> FVZ1E13 | F9: JAIR | G9: 0.54166667 | I9: SC | L9: DHL - CDV MEGA CURITIBA, APÓS COLETAR EM CURITIBA PARA DHL
A10: =VLOOKUP(F10,'CPF GPID NOME'!A:D,2,FALSE) -> MARCIO JOSE FIORI | B10: =VLOOKUP(F10,'CPF GPID NOME'!A:C,3,FALSE) -> 16728129847 | C10: =VLOOKUP(F10,'CPF GPID NOME'!A:D,4,FALSE) -> 25003421 | D10: =VLOOKUP(F10,'FROTA ESC.ESPE'!A:C,3,FALSE) -> R21894 | E10: =VLOOKUP(F10,'FROTA ESC.ESPE'!A:C,2,FALSE) -> FCZ9B41 | F10: MARCIO FIORI | G10: 0.54166667 | I10: SC | L10: DHL - CDV BAURU, APÓS LIGAR NA ESCALA (DESCARREGAR NO CDV ÀS 08:00 HRS DO DIA 02/01)
A11: =VLOOKUP(F11,'CPF GPID NOME'!A:D,2,FALSE) -> MARCIO JOSE DE OLIVEIRA | B11: =VLOOKUP(F11,'CPF GPID NOME'!A:C,3,FALSE) -> 35982164836 | C11: =VLOOKUP(F11,'CPF GPID NOME'!A:D,4,FALSE) -> 80861978 | D11: =VLOOKUP(F11,'FROTA ESC.ESPE'!A:C,3,FALSE) -> R01836 | E11: =VLOOKUP(F11,'FROTA ESC.ESPE'!A:C,2,FALSE) -> GHN0E58 | F11: MARCIO JOSÉ | G11: 0.54166667 | I11: SC | L11: DHL - FÁBRICA CURITIBA CIC, APÓS COLETAR EM CURITIBA PARA DHL
A12: =VLOOKUP(F12,'CPF GPID NOME'!A:D,2,FALSE) -> RENI DOMINGUES DOS SANTOS | B12: =VLOOKUP(F12,'CPF GPID NOME'!A:C,3,FALSE) -> 36124600803 | C12: =VLOOKUP(F12,'CPF GPID NOME'!A:D,4,FALSE) -> 40278474 | D12: =VLOOKUP(F12,'FROTA ESC.ESPE'!A:C,3,FALSE) -> R21884 | E12: =VLOOKUP(F12,'FROTA ESC.ESPE'!A:C,2,FALSE) -> FWC4B94 | F12: RENI | G12: 0.54166667 | I12: SC | L12: DHL - CDV PETROPOLIS, APÓS LIGAR NA ESCALA
A13: =VLOOKUP(F13,'CPF GPID NOME'!A:D,2,FALSE) -> MARCOS ALEXANDRE SALLES MARTINS | B13: =VLOOKUP(F13,'CPF GPID NOME'!A:C,3,FALSE) -> 20247171875 | C13: =VLOOKUP(F13,'CPF GPID NOME'!A:D,4,FALSE) -> 40278476 | D13: =VLOOKUP(F13,'FROTA ESC.ESPE'!A:C,3,FALSE) -> R01845 | E13: =VLOOKUP(F13,'FROTA ESC.ESPE'!A:C,2,FALSE) -> GDM2B57 | F13: SALLES | G13: 0.54166667 | I13: SC | L13: DHL - FÁBRICA CURITIBA CIC, APÓS COLETAR EM CURITIBA PARA DHL
... A15: =VLOOKUP(F15,'CPF GPID NOME'!A:D,2,FALSE) -> MARCIO VIEIRA DA SILVA | B15: =VLOOKUP(F15,'CPF GPID NOME'!A:C,3,FALSE) -> 27991659828 | C15: =VLOOKUP(F15,'CPF GPID NOME'!A:D,4,FALSE) -> 40045810 | D15: =VLOOKUP(F15,'FROTA ESC.ESPE'!A:C,3,FALSE) -> R21897 | E15: =VLOOKUP(F15,'FROTA ESC.ESPE'!A:C,2,FALSE) -> FXQ5A53 | F15: VIEIRA | G15: 0.54166667 | I15: SC | L15: DHL - FÁBRICA CURITIBA CIC, APÓS COLETAR EM CURITIBA PARA DHL

Sheet ESCALA 31.12.2025 
A1: NOME | B1: CPF | C1: GPID | D1: FROTA | E1: CAVALO | F1: MOTORISTA | G1: ESCALA | H1: APRESENTA | I1: VIAGEM | J1: VIAGEM | K1: VIAGEM | L1: DESTINO | O1: ////////////
A2: =VLOOKUP(F2,'CPF GPID NOME'!A:D,2,FALSE) -> OSMAR DE ALMEIDA | B2: =VLOOKUP(F2,'CPF GPID NOME'!A:C,3,FALSE) -> 12272348807 | C2: =VLOOKUP(F2,'CPF GPID NOME'!A:D,4,FALSE) -> 40108602 | D2: =VLOOKUP(F2,'FROTA ESC.ESPE'!A:C,3,FALSE) -> R21898 | E2: =VLOOKUP(F2,'FROTA ESC.ESPE'!A:C,2,FALSE) -> FXS7A81 | F2: ALMEIDA | G2: 0.083333333 | I2: SC | L2: DHL - CDV SANTOS, APÓS RETORNAR VAZIO PARA ITU
A3: =VLOOKUP(F3,'CPF GPID NOME'!A:D,2,FALSE) -> ALVARO ROVERI JUNIOR | B3: =VLOOKUP(F3,'CPF GPID NOME'!A:C,3,FALSE) -> 19813205806 | C3: =VLOOKUP(F3,'CPF GPID NOME'!A:D,4,FALSE) -> 40161559 | D3: =VLOOKUP(F3,'FROTA ESC.ESPE'!A:C,3,FALSE) -> R01846 | E3: =VLOOKUP(F3,'FROTA ESC.ESPE'!A:C,2,FALSE) -> FXN1C87 | F3: ALVARO | G3: 0.083333333 | I3: SC | L3: DHL - CDV MEGA ABC, APÓS RETORNAR VAZIO PARA ITU
A4: =VLOOKUP(F4,'CPF GPID NOME'!A:D,2,FALSE) -> CLAUDIO DE OLIVEIRA SILVA | B4: =VLOOKUP(F4,'CPF GPID NOME'!A:C,3,FALSE) -> 13900787875 | C4: =VLOOKUP(F4,'CPF GPID NOME'!A:D,4,FALSE) -> 40127273 | D4: =VLOOKUP(F4,'FROTA ESC.ESPE'!A:C,3,FALSE) -> R21901 | E4: =VLOOKUP(F4,'FROTA ESC.ESPE'!A:C,2,FALSE) -> GBH0E02 | F4: CLAUDIO | G4: 0.083333333 | H4: 0.053472222 | I4: SC | L4: DHL - CDV MEGA ABC, APÓS RETORNAR VAZIO PARA ITU
A5: =VLOOKUP(F5,'CPF GPID NOME'!A:D,2,FALSE) -> EDSON RICARDO MARTIN | B5: =VLOOKUP(F5,'CPF GPID NOME'!A:C,3,FALSE) -> 17728032860 | C5: =VLOOKUP(F5,'CPF GPID NOME'!A:D,4,FALSE) -> 40260112 | D5: =VLOOKUP(F5,'FROTA ESC.ESPE'!A:C,3,FALSE) -> R21907 | E5: =VLOOKUP(F5,'FROTA ESC.ESPE'!A:C,2,FALSE) -> GFS7C01 | F5: EDSON RICARDO | G5: 0.125 | I5: SC | L5: DHL - CDV SANTOS, APÓS RETORNAR VAZIO PARA ITU
A6: =VLOOKUP(F6,'CPF GPID NOME'!A:D,2,FALSE) -> HUDSON JUNIOR BATISTA | B6: =VLOOKUP(F6,'CPF GPID NOME'!A:C,3,FALSE) -> 15056516899 | C6: =VLOOKUP(F6,'CPF GPID NOME'!A:D,4,FALSE) -> 20200840 | D6: =VLOOKUP(F6,'FROTA ESC.ESPE'!A:C,3,FALSE) -> R21908 | E6: =VLOOKUP(F6,'FROTA ESC.ESPE'!A:C,2,FALSE) -> GHG2I72 | F6: HUDSON | G6: 0.125 | I6: SC | L6: DHL - CDV MEGA ABC, APÓS RETORNAR VAZIO PARA ITU
A7: =VLOOKUP(F7,'CPF GPID NOME'!A:D,2,FALSE) -> ANDERSON REMERSON DA SILVA | B7: =VLOOKUP(F7,'CPF GPID NOME'!A:C,3,FALSE) -> 22719521825 | C7: =VLOOKUP(F7,'CPF GPID NOME'!A:D,4,FALSE) -> 40286885 | D7: =VLOOKUP(F7,'FROTA ESC.ESPE'!A:C,3,FALSE) -> R01833 | E7: =VLOOKUP(F7,'FROTA ESC.ESPE'!A:C,2,FALSE) -> FRC9G83 | F7: REMERSON (DHL) | G7: 0.125 | H7: DHL | I7: - | L7: DHL - CDV MEGA ABC, APÓS RETORNAR VAZIO PARA DHL
A8: =VLOOKUP(F8,'CPF GPID NOME'!A:D,2,FALSE) -> EDILSON DOS ANJOS MOTA | B8: =VLOOKUP(F8,'CPF GPID NOME'!A:C,3,FALSE) -> 22022490282 | C8: =VLOOKUP(F8,'CPF GPID NOME'!A:D,4,FALSE) -> 40265472 | D8: =VLOOKUP(F8,'FROTA ESC.ESPE'!A:C,3,FALSE) -> R41525 | E8: =VLOOKUP(F8,'FROTA ESC.ESPE'!A:C,2,FALSE) -> FLX6568 | F8: MOTA | G8: 0.14583333 | I8: MDF CURITIBA | L8: ITU - FÁBRICA CURITIBA CIC ATÉ REGISTRO
A9: =VLOOKUP(F9,'CPF GPID NOME'!A:D,2,FALSE) -> LUIS FERNANDO PIO | B9: =VLOOKUP(F9,'CPF GPID NOME'!A:C,3,FALSE) -> 16741193804 | C9: =VLOOKUP(F9,'CPF GPID NOME'!A:D,4,FALSE) -> 20203603 | D9: =VLOOKUP(F9,'FROTA ESC.ESPE'!A:C,3,FALSE) -> A51621 | E9: =VLOOKUP(F9,'FROTA ESC.ESPE'!A:C,2,FALSE) -> PWZ6437 | F9: PIO | G9: 0.16666667 | I9: V | L9: REALIZAR 03 ITU - DHL E RETORNAR COM VAZIAS PARA ITU
A10: =VLOOKUP(F10,'CPF GPID NOME'!A:D,2,FALSE) -> WILLIAN SILVA GABRIELLI | B10: =VLOOKUP(F10,'CPF GPID NOME'!A:C,3,FALSE) -> 5972313545 | C10: =VLOOKUP(F10,'CPF GPID NOME'!A:D,4,FALSE) -> 9486051 | D10: =VLOOKUP(F10,'FROTA ESC.ESPE'!A:C,3,FALSE) -> R21885 | E10: =VLOOKUP(F10,'FROTA ESC.ESPE'!A:C,2,FALSE) -> GBH8G54 | F10: WILLIAN SILVA (MPW) | G10: 0.16666667 | I10: SC | L10: DHL - CDV MEGA ABC, APÓS RETORNAR VAZIO PARA ITU
A11: =VLOOKUP(F11,'CPF GPID NOME'!A:D,2,FALSE) -> DENILSON DE ANDRADE | B11: =VLOOKUP(F11,'CPF GPID NOME'!A:C,3,FALSE) -> 25741937845 | C11: =VLOOKUP(F11,'CPF GPID NOME'!A:D,4,FALSE) -> 40218096 | D11: =VLOOKUP(F11,'FROTA ESC.ESPE'!A:C,3,FALSE) -> R41967 | E11: =VLOOKUP(F11,'FROTA ESC.ESPE'!A:C,2,FALSE) -> TIZ8I61 | F11: PARANA | G11: 0.18055556 | I11: MANOBRA | L11: MANOBRA NA DHL ATÉ 13:40
A12: =VLOOKUP(F12,'CPF GPID NOME'!A:D,2,FALSE) -> UELITO DA SILVA ALVES | B12: =VLOOKUP(F12,'CPF GPID NOME'!A:C,3,FALSE) -> 30974848840 | C12: =VLOOKUP(F12,'CPF GPID NOME'!A:D,4,FALSE) -> 80224401 | D12: =VLOOKUP(F12,'FROTA ESC.ESPE'!A:C,3,FALSE) -> R21891 | E12: =VLOOKUP(F12,'FROTA ESC.ESPE'!A:C,2,FALSE) -> GKC8I64 | F12: ALVES | G12: 0.20833333 | I12: V | L12: REALIZAR 03 ITU - DHL E RETORNAR COM VAZIAS PARA ITU
A13: =VLOOKUP(F13,'CPF GPID NOME'!A:D,2,FALSE) -> WAGNER ROBERTO DE OLIVEIRA | B13: =VLOOKUP(F13,'CPF GPID NOME'!A:C,3,FALSE) -> 26268732847 | C13: =VLOOKUP(F13,'CPF GPID NOME'!A:D,4,FALSE) -> 80247356 | D13: =VLOOKUP(F13,'FROTA ESC.ESPE'!A:C,3,FALSE) -> R31340 | E13: =VLOOKUP(F13,'FROTA ESC.ESPE'!A:C,2,FALSE) -> FGQ6072 | F13: WAGNER (DHL) | G13: 0.25 | H13: DHL | I13: V | L13: REALIZAR 03 ITU - DHL E RETORNAR COM VAZIAS PARA ITU
A14: =VLOOKUP(F14,'CPF GPID NOME'!A:D,2,FALSE) -> MAURICIO FERNANDO SANTA ROSA | B14: =VLOOKUP(F14,'CPF GPID NOME'!A:C,3,FALSE) -> 68961359487 | C14: =VLOOKUP(F14,'CPF GPID NOME'!A:D,4,FALSE) -> 80312972 | D14: =VLOOKUP(F14,'FROTA ESC.ESPE'!A:C,3,FALSE) -> R01829 | E14: =VLOOKUP(F14,'FROTA ESC.ESPE'!A:C,2,FALSE) -> EUP1H09 | F14: SANTA ROSA | G14: 0.29166667 | I14: V | L14: REALIZAR 03 ITU - DHL E RETORNAR COM VAZIAS PARA ITU
A15: =VLOOKUP(F15,'CPF GPID NOME'!A:D,2,FALSE) -> ANDRE AGUINALDO DA SILVA | B15: =VLOOKUP(F15,'CPF GPID NOME'!A:C,3,FALSE) -> 35277185836 | C15: =VLOOKUP(F15,'CPF GPID NOME'!A:D,4,FALSE) -> 9486041 | D15: R41483 | E15: - | F15: AGUINALDO (MPW) | G15: 0.33333333 | I15: VAZIA | L15: ENGATAR UMA CARRETA VAZIA E SEGUIR PARA TROCA EM REGISTRO
A16: =VLOOKUP(F16,'CPF GPID NOME'!A:D,2,FALSE) -> JOSE ADIELSON DA SILVA | B16: =VLOOKUP(F16,'CPF GPID NOME'!A:C,3,FALSE) -> 35202906854 | C16: =VLOOKUP(F16,'CPF GPID NOME'!A:D,4,FALSE) -> 80172731 | D16: - | E16: - | F16: JOSÉ | G16: 0.33333333 | I16: APOIO | L16: APOIO À MANUTENÇÃO
A17: =VLOOKUP(F17,'CPF GPID NOME'!A:D,2,FALSE) -> CARLOS ALBERTO MESAS ROMERO | B17: =VLOOKUP(F17,'CPF GPID NOME'!A:C,3,FALSE) -> 13660753823 | C17: =VLOOKUP(F17,'CPF GPID NOME'!A:D,4,FALSE) -> 40124065 | D17: =VLOOKUP(F17,'FROTA ESC.ESPE'!A:C,3,FALSE) -> R21886 | E17: =VLOOKUP(F17,'FROTA ESC.ESPE'!A:C,2,FALSE) -> GFU4D23 | F17: ROMERO | G17: 0.33333333 | I17: SC | L17: DHL - CDV VITÓRIA, APÓS LIGAR FRETE RETORNO VERIFICAR COLETA
A18: =VLOOKUP(F18,'CPF GPID NOME'!A:D,2,FALSE) -> KLEBER GARCIA | B18: =VLOOKUP(F18,'CPF GPID NOME'!A:C,3,FALSE) -> 4350321942 | C18: =VLOOKUP(F18,'CPF GPID NOME'!A:D,4,FALSE) -> 40218084 | D18: =VLOOKUP(F18,'FROTA ESC.ESPE'!A:C,3,FALSE) -> A71676 | E18: =VLOOKUP(F18,'FROTA ESC.ESPE'!A:C,2,FALSE) -> GCD4A12 | F18: TOYS | G18: 0.33333333 | I18: SC | L18: DHL - CD UNIÃO DOS PALMARES MANUFATU (BITREM), APÓS LIGAR FRETE RETORNO VERIFICAR COLETA
A19: =VLOOKUP(F19,'CPF GPID NOME'!A:D,2,FALSE) -> AMAURI ARRUDA ALVES | B19: =VLOOKUP(F19,'CPF GPID NOME'!A:C,3,FALSE) -> 22245161858 | C19: =VLOOKUP(F19,'CPF GPID NOME'!A:D,4,FALSE) -> 9486039 | D19: =VLOOKUP(F19,'FROTA ESC.ESPE'!A:C,3,FALSE) -> R41536 | E19: =VLOOKUP(F19,'FROTA ESC.ESPE'!A:C,2,FALSE) -> FLX6787 | F19: AMAURI (MPW) | G19: 0.375 | I19: V | L19: REALIZAR 03 ITU - DHL E RETORNAR COM VAZIAS PARA ITU
A20: =VLOOKUP(F20,'CPF GPID NOME'!A:D,2,FALSE) -> BENEDITO LUIS SANTOS CORDEIRO | B20: =VLOOKUP(F20,'CPF GPID NOME'!A:C,3,FALSE) -> 36174313808 | C20: =VLOOKUP(F20,'CPF GPID NOME'!A:D,4,FALSE) -> 81066145 | D20: =VLOOKUP(F20,'FROTA ESC.ESPE'!A:C,3,FALSE) -> R01834 | E20: =VLOOKUP(F20,'FROTA ESC.ESPE'!A:C,2,FALSE) -> GHR3I92 | F20: BENEDITO | G20: 0.41666667 | I20: V | L20: REALIZAR 03 ITU - DHL E RETORNAR COM VAZIAS PARA ITU
A21: =VLOOKUP(F21,'CPF GPID NOME'!A:D,2,FALSE) -> LUCIANO ALVES SANTANA | B21: =VLOOKUP(F21,'CPF GPID NOME'!A:C,3,FALSE) -> 8584260641 | C21: =VLOOKUP(F21,'CPF GPID NOME'!A:D,4,FALSE) -> 80315813 | D21: =VLOOKUP(F21,'FROTA ESC.ESPE'!A:C,3,FALSE) -> R81546 | E21: =VLOOKUP(F21,'FROTA ESC.ESPE'!A:C,2,FALSE) -> BKY5B50 | F21: SANTANA | G21: 0.41666667 | I21: VAZIA | L21: ENGATAR UMA CARRETA VAZIA E SEGUIR PARA TROCA EM REGISTRO
A22: =VLOOKUP(F22,'CPF GPID NOME'!A:D,2,FALSE) -> NABOR CESAR MOREIRA FILHO | B22: =VLOOKUP(F22,'CPF GPID NOME'!A:C,3,FALSE) -> 094.942.848-52 | C22: =VLOOKUP(F22,'CPF GPID NOME'!A:D,4,FALSE) -> 40213000 | D22: =VLOOKUP(F22,'FROTA ESC.ESPE'!A:C,3,FALSE) -> A71683 | E22: =VLOOKUP(F22,'FROTA ESC.ESPE'!A:C,2,FALSE) -> FWB5C35 | F22: NABOR | G22: 0.45833333 | I22: V | L22: REALIZAR 03 ITU - DHL E RETORNAR COM VAZIAS PARA ITU
A23: =VLOOKUP(F23,'CPF GPID NOME'!A:D,2,FALSE) -> ANDERSON SANTOS PEREIRA | B23: =VLOOKUP(F23,'CPF GPID NOME'!A:C,3,FALSE) -> 21479622877 | C23: =VLOOKUP(F23,'CPF GPID NOME'!A:D,4,FALSE) -> 9486040 | D23: R41527 | F23: ANDERSON SANTOS (MPW) | G23: 0.54166667 | I23: V | L23: REALIZAR 03 ITU - DHL E RETORNAR COM VAZIAS PARA ITU

Sheet ESCALA 30.12.2025 
A1: NOME | B1: CPF | C1: GPID | D1: FROTA | E1: CAVALO | F1: MOTORISTA | G1: ESCALA | H1: APRESENTA | I1: VIAGEM | J1: VIAGEM | K1: VIAGEM | L1: DESTINO | O1: ////////////
A2: JOSE SEVERINO DE AGUIAR | B2: 37328361859 | C2: 81027970 | D2: R31311 | E2: FGQ5932 | F2: AGUIAR (DHL) | G2: 0.10416667 | H2: DHL | I2: - | L2: DHL - CDV MEGA ABC, APÓS COLETAR NA CBPA PARA DHL
A3: MATHEUS TIEPO PACHECO | B3: 44513387866 | C3: 80918725 | D3: R31353 | E3: FGQ6098 | F3: MATHEUS (DHL) | G3: 0.10416667 | H3: DHL | I3: - | L3: DHL - CDV MEGA ABC, APÓS LIGAR NA ESCALA
A4: ANDERSON REMERSON DA SILVA | B4: 22719521825 | C4: 40286885 | D4: R01833 | E4: FRC9G83 | F4: REMERSON (DHL) | G4: 0.10416667 | H4: DHL | I4: - | L4: DHL - CDV MEGA ABC, APÓS LIGAR NA ESCALA
A5: EMERSON APARECIDO ROSA | B5: 20247247871 | C5: 40046807 | D5: R11855 | E5: GDA0F01 | F5: EMERSON | G5: 0.125 | H5: 0.11805556 | I5: SC | L5: DHL - CDV TAUBATÉ, APÓS LIGAR NA ESCALA
A6: JOAQUIM BENEDITO LOPES | B6: 2713689856 | C6: 40106532 | D6: R41527 | E6: FLX6G47 | F6: LOPES | G6: 0.125 | H6: 0.24166667 | I6: SC | L6: BOLSÃO DHL - CDV CUMBICA, APÓS LIGAR NA ESCALA
A7: ODAIR ALVES | B7: 13251262840 | C7: 40126087 | D7: R21910 | E7: GJX7B25 | F7: ODAIR | G7: 0.125 | H7: 0.11805556 | I7: SC | L7: DHL - CDV CUMBICA, APÓS COLETAR NA CHEP ARAÇARIGUAMA PARA FÁBRICA SOROCABA
A8: JOSE PAULINO ALVES DA SILVA | B8: 50212885472 | C8: 20200850 | D8: R21911 | E8: GFX9C24 | F8: PAULINO | G8: 0.125 | H8: 0.21527778 | I8: SC | L8: DHL - CDV SANTOS, APÓS RETORNAR VAZIO PARA ITU
A9: ROBERTO TEIXEIRA SERRA | B9: 26394934852 | C9: 80994884 | D9: R41992 | F9: SERRA | G9: 0.125 | H9: 0.1125 | I9: SC | L9: DHL - CDV SANTOS, APÓS RETORNAR VAZIO PARA ITU
A10: EDILSON DOS ANJOS MOTA | B10: 22022490282 | C10: 40265472 | D10: R41525 | E10: FLX6568 | F10: MOTA | G10: 0.14583333 | H10: 0.12083333 | I10: V | L10: REALIZAR 03 ITU - DHL E RETORNAR COM VAZIAS PARA ITU
A11: ABEL JUSTINO DA SILVA | B11: 14992534864 | C11: 20200842 | D11: R21902 | E11: GBR8G23 | F11: ABEL | G11: 0.16666667 | H11: 0.15138889 | I11: SC | L11: DHL - CDV MEGA ABC, APÓS LIGAR NA ESCALA
A12: OSMAR DE ALMEIDA | B12: 12272348807 | C12: 40108602 | D12: R21898 | E12: FXS7A81 | F12: ALMEIDA | G12: 0.16666667 | H12: 0.15208333 | I12: SC | L12: DHL - CDV MEGA ABC, APÓS LIGAR NA ESCALA
A13: CLAUDIO DE OLIVEIRA SILVA | B13: 13900787875 | C13: 40127273 | D13: R21901 | E13: GBH0E02 | F13: CLAUDIO | G13: 0.16666667 | H13: 0.13472222 | I13: SC | L13: REALIZAR 02 ITU - DHL E RETORNAR COM VAZIAS PARA ITU
A14: DOUGLAS MASSUIA DOS SANTOS | B14: 33841126871 | C14: 80061172 | D14: R01842 | E14: GHS6H91 | F14: DOUGLAS | G14: 0.16666667 | H14: 0.37847222 | I14: SC | L14: DHL - CDV CUMBICA, APÓS COLETAR PALETES NO CDV PARA FÁBRICA LUCKY
A15: HUDSON JUNIOR BATISTA | B15: 15056516899 | C15: 20200840 | D15: R21908 | E15: GHG2I72 | F15: HUDSON | G15: 0.16666667 | H15: 0.15486111 | I15: SC | L15: DHL - CDV MEGA ABC, APÓS LIGAR NA ESCALA
A16: JAIR FRANCISCO ALVACETE | B16: 11704755824 | C16: 20200985 | D16: R21896 | E16: FVZ1E13 | F16: JAIR | G16: 0.16666667 | H16: 0.20902778 | I16: SC | L16: DHL - CDV MEGA ABC, APÓS LIGAR NA ESCALA
A17: JAQUELINE BATISTA RIBEIRO DE OLIVEIRA | B17: 33895981893 | C17: 80898051 | D17: R31963 | E17: ELE4C02 | F17: JAQUELINE (DHL) | G17: 0.16666667 | H17: DHL | I17: - | L17: DHL - CDV PIRACICABA (ELÉTRICO), APÓS RETORNAR VAZIO PARA DHL
A18: JONAS DOS REIS SANTOS | B18: 3441231627 | C18: 80343524 | D18: A71677 | E18: FUO1883 | F18: REIS | G18: 0.18055556 | H18: 0.20069444 | I18: V | L18: MANOBRA NA DHL ATÉ 13:40
A19: KLEBER GARCIA | B19: 4350321942 | C19: 40218084 | D19: A71676 | E19: GCD4A12 | F19: TOYS | G19: 0.18055556 | H19: 0.19097222 | I19: DUPLADO C/ REIS | L19: MANOBRA NA DHL ATÉ 13:40
A20: JOSE ADAILSON FERREIRA DE LIMA | B20: 7309225880 | C20: 20200743 | D20: R91550 | E20: EPA1I57 | F20: ADAILSON | G20: 0.20833333 | H20: 0.19444444 | I20: SC | L20: DHL - CDV PIRACICABA, APÓS LIGAR NA ESCALA
A21: ADALBERTO TEIXEIRA JUNIOR | B21: 26576670826 | C21: 40162666 | D21: R11854 | E21: - | F21: ADALBERTO | G21: 0.20833333 | H21: 0.20833333 | I21: SC | L21: DHL - CDV CUMBICA, APÓS LIGAR NA ESCALA
A22: ADAUTO TAVARES GREVISIRSKY | B22: 32365693873 | C22: 80109574 | D22: R91548 | E22: EFU8237 | F22: ADAUTO (DHL) | G22: 0.20833333 | H22: DHL | I22: - | L22: REALIZAR 03 QUAKER - DHL E RETORNAR COM VAZIAS PARA QUAKER
A23: RAFAEL CAMARGO SOMBINI | B23: 41397534800 | C23: 80869695 | D23: R01838 | E23: FRM9C53 | F23: CAMARGO | G23: 0.20833333 | H23: 0.20625 | I23: SC | L23: DHL - CDV SOROCABA, APÓS LIGAR NA ESCALA
A24: CLODOALDO ANDRINO ANTONANGELO | B24: 26857000808 | C24: 20216629 | D24: R11856 | E24: FIE2C01 | F24: CLODOALDO | G24: 0.20833333 | H24: 0.20694444 | I24: SC | L24: DHL - CDV CUMBICA, APÓS LIGAR NA ESCALA
A25: ERICK PITA DUTRA | B25: 32782909843 | C25: 81043503 | D25: R31345 | E25: FGQ6A76 | F25: ERICK (DHL) | G25: 0.20833333 | H25: DHL | I25: - | L25: REALIZAR 03 QUAKER - DHL E RETORNAR COM VAZIAS PARA QUAKER
A26: MANOEL HENRIQUE CANDIDO ROQUE | B26: 359.264.568-43 | C26: 9492760 | D26: R31346 | E26: FGQ6B01 | F26: MANOEL (MPW) | G26: 0.20833333 | H26: DHL | I26: - | L26: REALIZAR 03 QUAKER - DHL E RETORNAR COM VAZIAS PARA QUAKER
A27: MARCIO JOSE FIORI | B27: 16728129847 | C27: 25003421 | D27: R21894 | F27: MARCIO FIORI | G27: 0.20833333 | H27: 0.20902778 | I27: SC | L27: DHL - CDV CUMBICA, APÓS LIGAR NA ESCALA
A28: LUIS FERNANDO PIO | B28: 16741193804 | C28: 20203603 | D28: A51621 | E28: PWZ6437 | F28: PIO | G28: 0.20833333 | H28: 0.20277778 | I28: V | J28: V | K28: FNLZ | L28: REALIZAR 03 ITU - DHL E RETORNAR COM VAZIAS PARA ITU
A29: REGINALDO APARECIDO DA SILVA | B29: 7279004806 | C29: 25000510 | D29: R41535 | E29: FLX6550 | F29: REGINALDO | G29: 0.20833333 | H29: 0.18819444 | I29: SC | L29: DHL - CDV CUMBICA, APÓS LIGAR NA ESCALA
A30: ANTONIO MARCOS DE ARAUJO | B30: 16183839817 | C30: 80086888 | D30: R41536 | E30: FLX6787 | F30: ARAUJO | G30: 0.25 | H30: 0.23055556 | I30: V | J30: V | K30: FNLZ | L30: REALIZAR 03 ITU - DHL E RETORNAR COM VAZIAS PARA ITU
A31: CRISTIANO ROGÉRIO DE MORAES | B31: 23012070800 | C31: 9486044 | D31: R01832 | E31: FON8A35 | F31: CRISTIANO (MPW) | G31: 0.25 | H31: 0.22222222 | I31: V | L31: DHL - CDV SOROCABA, APÓS LIGAR NA ESCALA
A32: IVAN GASPAR DE MOURA | B32: 4564714805 | C32: 80178503 | D32: R01837 | E32: GJC1C37 | F32: IVAN | G32: 0.25 | H32: 0.23888889 | I32: V | L32: DHL - CDV MEGA ABC, APÓS LIGAR NA ESCALA
A33: RAFAEL ALEXANDRE CARDOSO DE CARVALHO | B33: 39527733871 | C33: 40260482 | D33: R01844 | E33: GFY3H56 | F33: RAFAEL | G33: 0.25 | H33: 0.23888889 | I33: V | L33: DHL - CDV CUMBICA, APÓS LIGAR NA ESCALA
A34: RENI DOMINGUES DOS SANTOS | B34: 36124600803 | C34: 40278474 | D34: R21884 | E34: FWC4B94 | F34: RENI | G34: 0.25 | H34: 0.23194444 | I34: V | L34: DHL - CDV CUMBICA, APÓS LIGAR NA ESCALA
A35: CARLOS ALBERTO MESAS ROMERO | B35: 13660753823 | C35: 40124065 | D35: R21886 | E35: GFU4D23 | F35: ROMERO | G35: 0.25 | H35: 0.24583333 | I35: V | L35: DHL - CDV CUMBICA, APÓS LIGAR NA ESCALA
A36: FERNANDO SATURNINO DE SIQUEIRA | B36: 28352241818 | C36: 9486046 | D36: R21887 | E36: GGV6H53 | F36: SATURNINO (MPW) | G36: 0.25 | H36: 0.24444444 | I36: V | L36: DHL - CDV CUMBICA, APÓS LIGAR NA ESCALA
A37: WILLIAN SILVA GABRIELLI | B37: 5972313545 | C37: 9486051 | D37: R21882 | F37: WILLIAN SILVA (MPW) | G37: 0.25 | H37: 0.25069444 | I37: V | J37: V | K37: FNLZ | L37: REALIZAR 03 ITU - DHL E RETORNAR COM VAZIAS PARA ITU
A38: HELIO RODRIGUES CORDEIRO | B38: 20246907851 | C38: 40286981 | D38: R21888 | E38: GHA3D47 | F38: CORDEIRO | G38: 0.29166667 | H38: 06:34 | L38: DHL - CDV CUMBICA, APÓS LIGAR NA ESCALA
A39: FLAVIO JOSE MARQUES DIAS | B39: 6272872801 | C39: 20200185 | D39: R21906 | E39: GFQ9F06 | F39: FLAVIO | G39: 0.29166667 | H39: 06:34 | L39: DHL - CDV CUMBICA, APÓS LIGAR NA ESCALA
A40: LOURIVAL DE SOUZA OMODEI | B40: 73885541904 | C40: 40119901 | D40: R21904 | E40: GFC4F16 | F40: LOURIVAL | G40: 0.29166667 | H40: 0.28541667 | I40: V | J40: V | K40: V | L40: REALIZAR 03 ITU - DHL E RETORNAR COM VAZIAS PARA ITU
...

Sheet CPF GPID NOME
A1: NOME | B1: NOME COMPLETO | C1: CPF | D1: GPID
A2: ABEL | B2: ABEL JUSTINO DA SILVA | C2: 14992534864 | D2: 20200842
A3: ADALBERTO | B3: ADALBERTO TEIXEIRA JUNIOR | C3: 26576670826 | D3: 40162666
A4: SANTOS (MPW) | B4: ADAUTO SANTOS DE SOUZA | C4: 35200522889 | D4: 9486037
A5: ADAUTO (DHL) | B5: ADAUTO TAVARES GREVISIRSKY | C5: 32365693873 | D5: 80109574
A6: ADEMIR | B6: ADEMIR DO PRADO | C6: 54812224934 | D6: 40107809
A7: MELO | B7: ADEMIR PINTO DE MELO | C7: 15058358875 | D7: 40120773
A8: ADERSON | B8: ADERSON CARVALHO DO NASCIMENTO | C8: 30804485453 | D8: 20200959
A9: NETO | B9: ALCIDES VIEIRA DE MORAES CASAGRANDE | C9: 31828417858 | D9: 80086835
A10: ALMIR | B10: ALMIR CARLOS DE SOUSA | C10: 22342327838 | D10: 40255608
A11: ALVARO | B11: ALVARO ROVERI JUNIOR | C11: 19813205806 | D11: 40161559
A12: AMAURI (MPW) | B12: AMAURI ARRUDA ALVES | C12: 22245161858 | D12: 9486039
A13: PEREIRA | B13: AMAURI FAZANI PEREIRA | C13: 26883586857 | D13: 80174399
... A110: DA CRUZ | B110: MIZAEL HERTER DA CRUZ | C110: 22418646840 | D110: 80312990
A111: NABOR | B111: NABOR CESAR MOREIRA FILHO | C111: 094.942.848-52 | D111: 40213000
A112: NERIVAN (DHL) | B112: NERIVAN SILVA LISBOA | C112: 5201413501 | D112: 80246401
A113: ODAIR | B113: ODAIR ALVES | C113: 13251262840 | D113: 40126087
A114: OSMAR SILVA (DHL) | B114: OSMAR DA SILVA CAMILO | C114: 10268541809 | D114: 40103891
A115: ALMEIDA | B115: OSMAR DE ALMEIDA | C115: 12272348807 | D115: 40108602
A116: RAFAEL | B116: RAFAEL ALEXANDRE CARDOSO DE CARVALHO | C116: 39527733871 | D116: 40260482
A117: CAMARGO | B117: RAFAEL CAMARGO SOMBINI | C117: 41397534800 | D117: 80869695
A118: REGELSON | B118: REGELSON GILMAR RODRIGUES | C118: 89196660082 | D118: 40213001
A119: REGINALDO | B119: REGINALDO APARECIDO DA SILVA | C119: 7279004806 | D119: 25000510
A120: RENI | B120: RENI DOMINGUES DOS SANTOS | C120: 36124600803 | D120: 40278474
A121: ROBERTO LOLI | B121: ROBERTO LOLLI | C121: 58923535915 | D121: 20200028
A122: QUEIROZ | B122: ROBERTO QUEIROZ DA SILVA | C122: 13801069826 | D122: 80109316
A123: SERRA | B123: ROBERTO TEIXEIRA SERRA | C123: 26394934852 | D123: 80994884
... A139: BEZERRA (MPW) | B139: JOSÉ CARLOS CANDIDO BEZERRA | C139: 36543095857 | D139: 9488950
A140: ROBSON (MPW) | B140: ROBSON BATISTA RIBEIRO | C140: 364.009.238-45 | D140: 9492757
A141: MANOEL (MPW) | B141: MANOEL HENRIQUE CANDIDO ROQUE | C141: 359.264.568-43 | D141: 9492760
A142: MAURICIO ROSA | B142: MAURICIO BARBOSA ROSA | C142: 297.995.308-30 | D142: 81074828
A143: RODRIGO (MPW) | B143: RODRIGO SANTOS VIEIRA | C143: 09448974604 | D143: 9493427
A144: ODIRLEI (MPW) | B144: ODIRLEI JOSE DOS SANTOS | C144: 27816632800 | D144: 9493428
A145: WELLINGTON (MPW) | B145: WELLINGTON LEANDRO DOS REIS | C145: 136.869.938-30 | D145: 9497501
A146: GOMES | B146: MARCOS ANTONIO GOMES | C146: 18226783828 | D146: 81124187

Sheet FROTA ESC.ESPE
A1: MOTORISTA | B1: PLACA | C1: FROTA | E1: ESCALA ESPECIAL DE QUARTA - FEIRA 31/12/2025
B2: BPQ2789 | C2: D82401
B3: QPZ6597 | C3: R82398 | E3: MOTORISTA | F3: DESTINO
A4: MANOBRA DHL | B4: BMR9063 | C4: D82402 | E4: SERGIO | F4: Escalar em viagem de no máx. 01 dias - veículo em manutenção (REVISÃO) - R41530
A5: MANOBRA ITU | B5: GHK8E12 | C5: D02403 | E5: ADAILSON | F5: Escalar em viagem de no máx. 13 dias - veículo em manutenção (REVISÃO) - R91550
A6: MANOBRA DHL | B6: GKA4B99 | C6: D02404 | E6: BORGES | F6: Escalar em viagem de no max. 01 dia no veículo do motorista Marcio josé - R01836
A7: MANOBRA ITU | B7: FGQ6071 | C7: R31309 | E7: CORDEIRO | F7: Escalar em viagem em CARRETA SIMPLES veículo R41980
A8: WANDERLEY | B8: FGQ5928 | C8: R31310 | E8: PIRES | F8: Escalar em viagem em CARRETA SIMPLES veículo A51632
A9: AGUIAR (DHL) | B9: FGQ5932 | C9: R31311 | E9: AGUINALDO (MPW) | F9: Escalar em viagem de no max. 01 dia no veículo do motorista Anderson folga - R41483
B10: FGQ5932 | C10: R31311 | E10: AMAURI (MPW) | F10: Escalar em viagem de no max. 01 dia no veículo do motorista Araujo folga - R41536
A11: MANOBRA SOROCABA | B11: FGQ6078 | C11: R31313 | E11: CLAYTON ALVES (MPW) | F11: Escalar em viagem de no max. 01 dia no veículo do motorista Fernandes folga R41992
A12: MANOBRA DHL | B12: FGQ6A59 | C12: R31316 | E12: WILLIAN SILVA (MPW) | F12: Escalar em viagem de no max. 01 dia no veículo do motorista Eduardo almeida folga R21885
B13: FGQ5930 | C13: R31320 | E13: ADAILSON | F13: Escalar em viagem de no max. 01 dia no veículo do motorista Fonseca folga R81539
A14: MANOBRA DHL | B14: FGQ5930 | C14: R31320 | E14: ANDERSON SANTOS (MPW) | F14: Escalar em viagem de no max. 01 dia no veículo do motorista Lopes folga R41527
B15: FGQ6A91 | C15: R31325 | E15: ROBSON (MPW) | F15: Escalar em viagem de no max. 01 dia no veículo do motorista Tapia folga R01830
A16: LUIS FABIO (DHL) | B16: FGQ5931 | C16: R31326 | E16: EDISON SILVA | F16: Escalar em viagem de no max. 01 dia no veículo do motorista Pereira R41531
B17: FGQ5931 | C17: R31326 | E17: NETO | F17: Escalar em viagem de no max. 01 dia no veículo do motorista Da Cruz R31347
A18: MANOBRA DHL | B18: FGQ6080 | C18: R31335 | E18: ERENO (MPW) | F18: Escalar em viagem de no max. 06 dias no veículo do motorista Joao lopes volta de férias dia 06/01/26)
A19: MANOBRA DHL | B19: FGQ6090 | C19: R31337 | E19: NABOR | F19: Escalar em viagem para realizar ITU X DHL veículo em teste - A71683
A20: MANOBRA ITU | B20: FGQ5927 | C20: R31339 | E20: SEVERINO | F20: Escalar em viagem de no max. 06 dias no veículo do motorista Marcos alves volta de férias dia 05/01/26) - R41498
A21: WAGNER (DHL) | B21: FGQ6072 | C21: R31340 | E21: MOTA | F21: Escalar em viagem de no max. 06 dias no veículo do motorista Silva Volta de férias dia 05/01/26) - R41525
A22: NERIVAN (DHL) | B22: FGQ6072 | C22: R31340 | E22: SILVIO DIAS | F22: Escalar em viagem para realizar ITU X DHL veículo em teste - R41526
A23: MANOBRA DHL | B23: FGQ6073 | C23: R31343 | E23: JOSÉ | F23: Escalar em viagem as 08:00h - APOIO A MANUTENÇÂO
B24: FGQ6A76 | C24: R31345 | E24: DANIEL | F24: Escalar em viagem circuito REGISTRO veículo projeto ECOTORQUE - R91540
A25: ERICK (DHL) | B25: FGQ6A76 | C25: R31345 | E25: ADAUTO (DHL) | F25: Escalar em viagem circuito REGISTRO veículo projeto ECOTORQUE - R91548
A26: MANOEL (MPW - DHL) | B26: FGQ6B01 | C26: R31346 | E26: WELLIGTON (MPW - DHL) | F26: Escalar em viagem periodo da tarde, circuito DHL x SOROCABA veículo projeto ECOTORQUE - R31346
A27: WELLIGTON (MPW - DHL) | B27: FGQ6B01 | C27: R31346 | E27: MANOEL (MPW - DHL) | F27: Escalar em viagem periodo da manha, circuito DHL x SOROCABA veículo projeto ECOTORQUE - R31346
A28: NETO | B28: FGQ6064 | C28: R31347 | E28: HERON | F28: Escalar em viagem cricuito AÇUCAR veículo projeto ECOTORQUE - R81549
A29: SIMULADOR | B29: FGQ6065 | C29: R31348 | E29: ADRIANO | F29: Escalar em viagem cricuito AÇUCAR veículo projeto ECOTORQUE - R81548
A30: MATHEUS (DHL) | B30: FGQ6098 | C30: R31353 | E30: JORGE | F30: Escalar em viagem cricuito AÇUCAR veículo projeto ECOTORQUE - R81552
A31: ANDRÉ (DHL) | B31: FGQ6098 | C31: R31353 | E31: EMERSON | F31: Escalar em viagem de no máx 02 dias veículo em manutenção REVISÃO/CODEMA dia 02/01/2026 as 07:30h - R11855
A32: AURELIO | B32: FLX6645 | C32: R41482
A33: ANDERSON | B33: FLX6H89 | C33: R41483
A34: LUIZ | B34: FLX6H84 | C34: R41486
A35: CARLITO | B35: FLX6651 | C35: R41491
A36: REGELSON | B36: FLX6788 | C36: R41495
A37: ERENO (MPW) | B37: FLX6573 | C37: R41493
A38: LAURO | B38: FLX6799 | C38: R41492
A39: NASCIMENTO | B39: FLX6630 | C39: R41496
A40: SEVERINO | B40: FLX6572 | C40: R41498
...

Sheet MOTORISTAS 7L
A1: MOTORISTAS SETE LAGOAS
A2: NOME | B2: CPF | C2: GPID | D2: FROTA
A3: ADELIO DA SILVA | B3: 453.447.446-68 | C3: 20203347
A4: ADRIANO DOS SANTOS AVELAR | B4: 003.091.556-22 | C4: 20204320 | D4: R41966 | E4: OK
A5: ALINE LAINE MARTINS FARIA | B5: 093.919.266-73 | C5: 80960029
A6: ANA LUCIA ALVES DA SILVA | B6: 076.307.116-11 | C6: 80994968 | D6: R41509
A7: ANDERSON CARLOS DE MELO | B7: 534.619.166-68 | C7: 81202192 | D7: R41506
A8: ANDERSON PEREIRA RAMOS | B8: 056.248.096-03 | C8: 81133030 | D8: R31352
A9: ANDRÉ DIAS FIGUEIREDO | B9: 058.882.816-54 | C9: 80176099
A10: ANTONIO CARLOS DE OLIVEIRA | B10: 100.325.876-00 | C10: 80884536 | D10: R31943
A11: ANTONIO CARLOS DE OLIVEIRA | B11: 109.301.436-98 | C11: 9465547 | D11: R91557 | E11: QQV9899
A12: ANTONIO DA COSTA MONTEIRO | B12: 969.038.996-34 | C12: 40123562 | D12: R91556
A13: ANTONIO JUNIOR DOS SANTOS | B13: 856.346.204-06 | C13: 40280673 | D13: R41497
A14: ARMANDO FERREIRA COSTA | B14: 826.828.366-15 | C14: 80176903 | D14: R31941
A15: ARONE BORGES RIBEIRO | B15: 068.138.506-52 | C15: 80997596
A16: ATOS DA SILVA REGINALDO | B16: 091.975.616-65 | C16: 81151671
A17: CARLOS ALBERTO BARBOSA RODRIGUES | B17: 077.355.566-83 | C17: 81012875 | D17: R31342
A18: CARLOS ALBERTO DE FREITAS ROCHA | B18: 003.099.376-80 | C18: 40214903 | D18: R41488
A19: CLAUDIO HENRIQUE NUNES CARVALHO | B19: 003.092.766-83 | C19: 25003639 | D19: R31946 | E19: R31347
A20: CLAYTON HENRIQUE VIANA | B20: 075.307.096-07 | C20: 9449985 | D20: R11852
A21: CLEBER DE SOUZA SILVA | B21: 070.573.246-00 | C21: 80143955 | D21: A71622
A22: CLERIO GOMES DA SILVA | B22: 694.839.226-15 | C22: 40045630
A23: DARLAN DE ALMEIDA SANTOS | B23: 108.782.876-71 | C23: 80994783 | D23: R31336
A24: DELSON DE JESUS CAMPELO | B24: 036.059.026-85 | C24: 40191146
A25: DENIO CARLOS BARBOSA | B25: 012.367.966-40 | C25: 80176392
A26: DIOGO PIRES DE SOUSA | B26: 060.280.746-83 | C26: 40279541
A27: EDVALDO LOURENÇO SIQUEIRA | B27: 054.852.036-47 | C27: 80884541 | D27: A71684 | E27: OK
A28: ELCIO ARAUJO DOS SANTOS JUNIOR | B28: 086.477.486-97 | C28: 81187060 | D28: R31336
A29: ELIAS OLIVEIRA GOMES | B29: 082.210.366-41 | C29: 80870410
A30: ERNANDO ANDRADE PEREIRA | B30: 055.769.186-90 | C30: 40146532
A31: EVALDO MOREIRA DOS SANTOS | B31: 103.286.766-32 | C31: 80995122 | D31: R31950
A32: EVANIO CORREA DA SILVA | B32: 957.827.966-34 | C32: 9449194 | D32: R41517
A33: FABIO DA SILVA ANDRADE | B33: 079.768.646-02 | C33: 80251780 | D33: R41516
A34: FABIO DE SOUZA OLIVEIRA | B34: 060.298.406-81 | C34: 80176420
A35: FABRICIO DINALI DA SILVA | B35: 126.360.217-79 | C35: 80334073
A36: FERNANDO ANDRADE PEREIRA | B36: 050.880.576-79 | C36: 81006178
A37: FLAVIO HENRIQUE MARTINS RIBEIRO | B37: 46007 | C37: 9449197
A38: GUILHERME ASSIS TELES | B38: 048.513.226-58 | C38: 40188743 | D38: R41479
A39: HALISSON CLARETE BATISTA GOMES | B39: 061.145.966-33 | C39: 80324590
A40: HILDEMARIO ALVES SILVA | B40: 356.943.605-59 | C40: 80176500
...

Sheet MOTORISTAS CIC
A1: MOTORISTAS CURITIBA
A2: NOME | B2: CPF | C2: GPID | D2: FROTA
A3: ACÁCIO MACHOWSKY | B3: 817.501.619-15 | C3: 20201422 | D3: R41487
A4: ADÃO GERALDO DOS SANTOS | B4: 796.430.519-00 | C4: 80189666 | D4: A71681
A5: ADÃO SIMÕES CARDOSO | B5: 478.826.469-20 | C5: 20200472
A6: ADILSON DE MATOS | B6: 759.695.489-87 | C6: 81145727
A7: ADRIANO MARCOS DE ARRUDA | B7: 033.706.099-16 | C7: 40211433 | D7: R41474
A8: ALESSANDRO MARÇAL DA SILVA | B8: 005.890.669-00 | C8: 80312833
A9: ALEX SANDRO MARCEL RIBEIRO DOS SANTOS | B9: 876.013.389-91 | C9: 80251163
A10: ALFREDO ROSA JUNIOR | B10: 099.750.168-55 | C10: 80318046 | D10: R41489
A11: ALISON BORGES PAULINO | B11: 062.564.589.82 | C11: 81033484 | D11: R41480
A12: ANA LOURENÇO BANDEIRA | B12: 271.835.758-45 | C12: 80176454
A13: ANTONIO CARLOS THOMAZETTI | B13: 759.849.119-49 | C13: 80184072 | D13: R41499
A14: CARLOS MIGUEL GONÇALVES DOS SANTOS | B14: 011.927.489-21 | C14: 81111965 | D14: l
A15: CARLOS ROBERTO LUFT | B15: 737.480.219-68 | C15: 40100474 | D15: R91551
A16: CLAUDEMIR ALVES DE FRANÇA | B16: 020.813.299-64 | C16: 81058191
A17: CLAUDEMIR PEREIRA DA SILVA | B17: 053.195.039-54 | C17: 80303039
A18: CLEITERSON DA SILVA PAULA | B18: 042.243.939-80 | C18: 80007697 | D18: A71688
A19: CLEVERSON DA SILVA BUENO DE ANDRADE | B19: 030.624.919-73 | C19: 80314090
A20: CLEVERSON GONÇALVES DA COSTA | B20: 032.387.579-38 | C20: 80880831
A21: DANIEL MONTEIRO DA SILVA | B21: 025.604.909-27 | C21: 80315465 | D21: A71678
A22: DAVI LUIZ MOREIRA | B22: 045.372.434-57 | C22: 80315321
A23: DEYVERSON RANDERSON MAGNO DA SILVA | B23: 004.050.382-83 | C23: 80801781 | D23: A51635
A24: EDEMILSON ANTUNES | B24: 054.031.559-10 | C24: 80184065
A25: EDSON ESTEVÃO DOS SANTOS | B25: 638.300.439-53 | C25: 81115224
A26: ELIANE DE OLIVEIRA FERREIRA | B26: 064.337.229-62 | C26: 80302627
A27: ELIEZER ROBERTO MAIA | B27: 025.206.109-80 | C27: 81211088 | D27: A51635
A28: ERILSON MAURICIO BELLO | B28: 816.166.359-91 | C28: 80184065 | D28: R91544
A29: EVANDRO ROGÉRIO DA CRUZ | B29: 018.220.189-94 | C29: 40185783
A30: EVANIO FELICETTI | B30: 022.269.589-75 | C30: 40144736 | D30: A71689
A31: FABIO GOMES DE ANDRADE | B31: 004.087.209-21 | C31: 20203151
A32: FERNANDO DE PAULA | B32: 024.405.179-84 | C32: 40007867 | D32: R91559
A33: GIOVANI CLAUDINO NEGOSEKI | B33: 029.657.349-37 | C33: 40260114
A34: ISRAEL SILVERIO DE SOUZA | B34: 262.337.988-25 | C34: 40282774
A35: JAIR FREZER JUNIOR | B35: 022.201.539-08 | C35: 40282774 | D35: A51637
A36: JEFFERSON RIBEIRO DEZIDERIO | B36: 009.102.509-52 | C36: 40178732 | D36: R21903
A37: JOÃO ACIR DE OLIVEIRA JUNIOR | B37: 023.089.199-30 | C37: 81016751
A38: JOÃO CARLOS MORO | B38: 875.673.859-53 | C38: 80009306 | D38: R91546
A39: JOSÉ CARLOS CHUESZ | B39: 035.553.639-05 | C39: 40124899 | D39: R21913
A40: JOSÉ ISMAIL MEDEIROS | B40: 967.465.729-00 | C40: 40123098
...

Sheet SOLICITAÇÕES
A1: CDV | H1: CABREÚVA
A2: DT | B2: STO | C2: DESTINO | D2: DATA SAÍDA | E2: HR. SUBIR PICKINGS | F2: HR. SAÍDA CARGA | H2: DT | I2: STO | J2: DESTINO | K2: DATA SAÍDA | L2: HR. SUBIR PICKINGS
H3: 12707552 | I3: 4521892716 | J3: CD CABREUVA MANUFATURA (DHL) | K3: 46012 | L3: 0.20833333
H4: 12707559 | I4: 4521892714 | J4: CD CABREUVA MANUFATURA (DHL) | K4: 46012 | L4: 0.20833333
H5: 12707509 | I5: 4521892713 | J5: CD CABREUVA MANUFATURA (DHL) | K5: 46012 | L5: 0.20833333
H6: 12707400 | I6: 4521892711 | J6: CD CABREUVA MANUFATURA (DHL) | K6: 46012 | L6: 0.375
H7: 12737349 | I7: 4521938283 | J7: CD CABREUVA MANUFATURA (DHL) | K7: 46011 | L7: 0.625
H8: 12737351 | I8: 4521938284 | J8: CD CABREUVA MANUFATURA (DHL) | K8: 46012 | L8: 0.66666667
H9: 12737247 | I9: 4521938626 | J9: CD CABREUVA DISTRIBUIDORA (DHL) | K9: 46012 | L9: 0.58333333
H10: 12743232 | I10: 4521950840 | J10: CD CABREUVA MANUFATURA (DHL) | K10: 46012 | L10: 0.20833333
H11: 12743282 | I11: 4521950841 | J11: CD CABREUVA MANUFATURA (DHL) | K11: 46012 | L11: 0.20833333
H12: 12743761 | I12: 4521950842 | J12: CD CABREUVA MANUFATURA (DHL) | K12: 46012 | L12: 0.20833333
H13: 12743243 | I13: 4521950843 | J13: CD CABREUVA MANUFATURA (DHL) | K13: 46012 | L13: 0.20833333
H14: 12742720 | I14: 4521950844 | J14: CD CABREUVA MANUFATURA (DHL) | K14: 46012 | L14: 0.25
... H33: 12743186 | I33: 4521951647 | J33: CD CABREUVA DISTRIBUIDORA (DHL) | K33: 46012 | L33: 0.45833333
